Workbook

Sheet Calculo para velocidad angular
A1: t (s) | B1: θ Tracker | C1: θ continuo | H1: tiempo | I1: posición | J1: w rad/s | K1: a angular rad/s2 | N1: tiempo | O1: posición | P1: w rad/s | Q1: a angular rad/s2 | S1: Barra AB | Y1: Medidas del mecanismo
A2: 0 | B2: 7.6 | C2: 7.6 | H2: =A17 -> 0.5 | I2: =C17 -> -85.4 | J2: =((C18-C16)/(A18-A16))*(PI()/180) -> -2.8654659 | N2: 0.533 | O2: -92.1° | P2: -2.5122 | Q2: 6.7098 | S2: tiempo | T2: posición | U2: w rad/s | V2: a angular rad/s2 | W2: posición rad | Y2: AB | Z2: 0.05
A3: 0.033 | B3: 1.2 | C3: 1.2 | H3: =A18 -> 0.533 | I3: =C18 -> -92.1 | J3: =((C19-C17)/(A19-A17))*(PI()/180) -> -2.5122163 | K3: =(J4-J2)/(H4-H2) -> 6.7097687 | N3: 0.9 | O3: -145.3° | P3: -2.2142 | Q3: 9.2547 | S3: 0.533 | T3: -92.1 | U3: -2.5122 | V3: 6.7098 | W3: =T3*(PI()/180) -> -1.6074482 | Y3: BC | Z3: 0.1
A4: 0.067 | B4: -6.2 | C4: -6.2 | H4: =A19 -> 0.566 | I4: =C19 -> -94.9 | J4: =((C20-C18)/(A20-A18))*(PI()/180) -> -2.4226212 | K4: =(J5-J3)/(H5-H3) -> -4.8835806 | N4: 1.266 | O4: -185.3° | P4: -1.428 | Q4: 9.4726 | S4: 0.9 | T4: -145.3 | U4: -2.2142 | V4: 9.2547 | W4: =T4*(PI()/180) -> -2.5359634 | Y4: CD | Z4: 0.1
A5: 0.1 | B5: -12.6 | C5: -12.6 | H5: =A20 -> 0.6 | I5: =C20 -> -101.4 | J5: =((C21-C19)/(A21-A19))*(PI()/180) -> -2.8394162 | K5: =(J6-J4)/(H6-H4) -> -4.8894715 | N5: 1.633 | O5: -226.8° | P5: -2.084 | Q5: -11.0926 | S5: 1.266 | T5: -185.3 | U5: -1.428 | V5: 9.4726 | W5: =T5*(PI()/180) -> -3.2340951 | Y5: DP | Z5: 0.115
A6: 0.133 | B6: -20.1 | C6: -20.1 | H6: =A21 -> 0.633 | I6: =C21 -> -105.8 | J6: =((C22-C20)/(A22-A20))*(PI()/180) -> -2.7502158 | K6: =(J7-J5)/(H7-H5) -> 2.3681537 | N6: 1.899 | O6: -270.4° | P6: -4.715 | Q6: -21.873 | S6: 1.633 | T6: -226.8 | U6: -2.084 | V6: -11.0926 | W6: =T6*(PI()/180) -> -3.9584067 | Y6: Dx | Z6: 0.0936
A7: 0.167 | B7: -25.9 | C7: -25.9 | H7: =A22 -> 0.666 | I7: =C22 -> -111.8 | J7: =((C23-C21)/(A23-A21))*(PI()/180) -> -2.6831181 | K7: =(J8-J6)/(H8-H6) -> 2.9454648 | N7: 2.099 | O7: -316.4° | P7: -3.9667 | Q7: -12.6302 | S7: 1.899 | T7: -270.4 | U7: -4.715 | V7: -21.873 | W7: =T7*(PI()/180) -> -4.7193703 | Y7: Dy | Z7: 0.08499
A8: 0.2 | B8: -32.1 | C8: -32.1 | H8: =A23 -> 0.7 | I8: =C23 -> -116.1 | J8: =((C24-C22)/(A24-A22))*(PI()/180) -> -2.5528697 | K8: =(J9-J7)/(H9-H7) -> 2.5507725 | N8: 0.633 | O8: -105.8 | P8: -2.75 | Q8: 2.3681537 | S8: 2.099 | T8: -316.4 | U8: -3.9667 | V8: -12.6302 | W8: =T8*(PI()/180) -> -5.5222218
A9: 0.233 | B9: -38.2 | C9: -38.2 | H9: =A24 -> 0.733 | I9: =C24 -> -121.6 | J9: =((C25-C23)/(A25-A23))*(PI()/180) -> -2.5122163 | K9: =(J10-J8)/(H10-H8) -> -2.3681537 | N9: 0.766 | O9: -125.6 | P9: -2.7092 | Q9: 1.337
A10: 0.267 | B10: -44.2 | C10: -44.2 | H10: =A25 -> 0.766 | I10: =C25 -> -125.6 | J10: =((C26-C24)/(A26-A24))*(PI()/180) -> -2.7091678 | K10: =(J11-J9)/(H11-H9) -> 1.337241 | N10: 1.766 | O10: -246.9 | P10: -2.4329 | Q10: -7.89
A11: 0.3 | B11: -50.5 | C11: -50.5 | H11: =A26 -> 0.8 | I11: =C26 -> -132 | J11: =((C27-C25)/(A27-A25))*(PI()/180) -> -2.4226212 | K11: =(J12-J10)/(H12-H10) -> 10.438727
A12: 0.333 | B12: -55.6 | C12: -55.6 | H12: =A27 -> 0.833 | I12: =C27 -> -134.9 | J12: =((C28-C26)/(A28-A26))*(PI()/180) -> -2.0097731 | K12: =(J13-J11)/(H13-H11) -> -4.3416151
A13: 0.367 | B13: -63.6 | C13: -63.6 | H13: =A28 -> 0.866 | I13: =C28 -> -139.6 | J13: =((C29-C27)/(A29-A27))*(PI()/180) -> -2.7091678 | K13: =(J14-J12)/(H14-H12) -> -3.0515015
A14: 0.4 | B14: -68.9 | C14: -68.9 | H14: =A29 -> 0.9 | I14: =C29 -> -145.3 | J14: =((C30-C28)/(A30-A28))*(PI()/180) -> -2.2142237 | K14: =(J15-J13)/(H15-H13) -> 9.2546503
A15: 0.433 | B15: -74.2 | C15: -74.2 | H15: =A30 -> 0.933 | I15: =C30 -> -148.1 | J15: =((C31-C29)/(A31-A29))*(PI()/180) -> -2.0891062 | K15: =(J16-J14)/(H16-H14) -> -1.5787691 | P15: Velocidad AB
A16: 0.466 | B16: -81.1 | C16: -81.1 | H16: =A31 -> 0.966 | I16: =C31 -> -153.2 | J16: =((C32-C30)/(A32-A30))*(PI()/180) -> -2.3184224 | K16: =(J17-J15)/(H17-H15) -> -4.5890341 | P16: =AVERAGE(J:J) -> -2.7019469
A17: 0.5 | B17: -85.4 | C17: -85.4 | H17: =A32 -> 1 | I17: =C32 -> -157 | J17: =((C33-C31)/(A33-A31))*(PI()/180) -> -2.3965715 | K17: =(J18-J16)/(H18-H16) -> -5.2606001
A18: 0.533 | B18: -92.1 | C18: -92.1 | H18: =A33 -> 1.033 | I18: =C33 -> -162.4 | J18: =((C34-C32)/(A34-A32))*(PI()/180) -> -2.6708826 | K18: =(J19-J17)/(H19-H17) -> 12.235461
A19: 0.566 | B19: -94.9 | C19: -94.9 | H19: =A34 -> 1.066 | I19: =C34 -> -167.1 | J19: =((C35-C33)/(A35-A33))*(PI()/180) -> -1.5890311 | K19: =(J20-J18)/(H20-H18) -> 27.422277
A20: 0.6 | B20: -101.4 | C20: -101.4 | H20: =A35 -> 1.1 | I20: =C35 -> -168.5 | J20: =((C36-C34)/(A36-A34))*(PI()/180) -> -0.83359009 | K20: =(J21-J19)/(H21-H19) -> 3.1928838
A21: 0.633 | B21: -105.8 | C21: -105.8 | H21: =A36 -> 1.133 | I21: =C36 -> -170.3 | J21: =((C37-C35)/(A37-A35))*(PI()/180) -> -1.3751079 | K21: =(J22-J20)/(H22-H20) -> -13.81423
A22: 0.666 | B22: -111.8 | C22: -111.8 | H22: =A37 -> 1.166 | I22: =C37 -> -173.7 | J22: =((C38-C36)/(A38-A36))*(PI()/180) -> -1.7453293 | K22: =(J23-J21)/(H23-H21) -> -11.135106
A23: 0.7 | B23: -116.1 | C23: -116.1 | H23: =A38 -> 1.199 | I23: =C38 -> -176.9 | J23: =((C39-C37)/(A39-A37))*(PI()/180) -> -2.1100249 | K23: =(J24-J22)/(H24-H22) -> -6.6096229
A24: 0.733 | B24: -121.6 | C24: -121.6 | H24: =A39 -> 1.233 | I24: =C39 -> -181.8 | J24: =((C40-C38)/(A40-A38))*(PI()/180) -> -2.188174 | K24: =(J25-J23)/(H25-H23) -> 10.179526
A25: 0.766 | B25: -125.6 | C25: -125.6 | H25: =A40 -> 1.266 | I25: =C40 -> -185.3 | J25: =((C41-C39)/(A41-A39))*(PI()/180) -> -1.4279967 | K25: =(J26-J24)/(H26-H24) -> 9.4726147
A26: 0.8 | B26: -132 | C26: -132 | H26: =A41 -> 1.299 | I26: =C41 -> -187.2 | J26: =((C42-C40)/(A42-A40))*(PI()/180) -> -1.5629814 | K26: =(J27-J25)/(H27-H25) -> -11.34593
A27: 0.833 | B27: -134.9 | C27: -134.9 | H27: =A42 -> 1.333 | I27: =C42 -> -191.3 | J27: =((C43-C41)/(A43-A41))*(PI()/180) -> -2.188174 | K27: =(J28-J26)/(H28-H26) -> -5.0897631
A28: 0.866 | B28: -139.6 | C28: -139.6 | H28: =A43 -> 1.366 | I28: =C43 -> -195.6 | J28: =((C44-C42)/(A44-A42))*(PI()/180) -> -1.9039955 | K28: =(J29-J27)/(H29-H27) -> 1.9734614
... A33: 1.033 | B33: -162.4 | C33: -162.4 | H33: =A48 -> 1.533 | I33: =C48 -> -217.1 | J33: =((C49-C47)/(A49-A47))*(PI()/180) -> -2.2663231 | K33: =(J34-J32)/(H34-H32) -> 10.438727
A34: 1.066 | B34: -167.1 | C34: -167.1 | H34: =A49 -> 1.566 | I34: =C49 -> -219.4 | J34: =((C50-C48)/(A50-A48))*(PI()/180) -> -2.0097731 | K34: =(J35-J33)/(H35-H33) -> 5.1309996 | O34: =AVERAGE(P:P) -> -2.7469176 | P34: =AVERAGE(J:J) -> -2.7019469
A35: 1.1 | B35: -168.5 | C35: -168.5 | H35: =A50 -> 1.599 | I35: =C50 -> -224.7 | J35: =((C51-C49)/(A51-A49))*(PI()/180) -> -1.9276771 | K35: =(J36-J34)/(H36-H34) -> -1.1074947
A36: 1.133 | B36: -170.3 | C36: -170.3 | H36: =A51 -> 1.633 | I36: =C51 -> -226.8 | J36: =((C52-C50)/(A52-A50))*(PI()/180) -> -2.0839752 | K36: =(J37-J35)/(H37-H35) -> -11.09262
A37: 1.166 | B37: -173.7 | C37: -173.7 | H37: =A52 -> 1.666 | I37: =C52 -> -232.7 | J37: =((C53-C51)/(A53-A51))*(PI()/180) -> -2.6708826 | K37: =(J38-J36)/(H38-H36) -> -11.446076
A38: 1.199 | B38: -176.9 | C38: -176.9 | H38: =A53 -> 1.699 | I38: =C53 -> -236.9 | J38: =((C54-C52)/(A54-A52))*(PI()/180) -> -2.8394162 | K38: =(J39-J37)/(H39-H37) -> 0.98378523
A39: 1.233 | B39: 178.2 | C39: -181.8 | H39: =A54 -> 1.733 | I39: =C54 -> -243.6 | J39: =((C55-C53)/(A55-A53))*(PI()/180) -> -2.604969 | K39: =(J40-J38)/(H40-H38) -> 6.0676574
A40: 1.266 | B40: 174.7 | C40: -185.3 | H40: =A55 -> 1.766 | I40: =C55 -> -246.9 | J40: =((C56-C54)/(A56-A54))*(PI()/180) -> -2.4328832 | K40: =(J41-J39)/(H41-H39) -> -7.8938456
A41: 1.299 | B41: 172.8 | C41: -187.2 | H41: =A56 -> 1.799 | I41: =C56 -> -252.8 | J41: =((C57-C55)/(A57-A55))*(PI()/180) -> -3.1259628 | K41: =(J42-J40)/(H42-H40) -> -10.344472
A42: 1.333 | B42: 168.7 | C42: -191.3 | H42: =A57 -> 1.833 | I42: =C57 -> -258.9 | J42: =((C58-C56)/(A58-A56))*(PI()/180) -> -3.1259628 | K42: =(J43-J41)/(H43-H41) -> 1.2665498
A43: 1.366 | B43: 164.4 | C43: -195.6 | H43: =A58 -> 1.866 | I43: =C58 -> -264.8 | J43: =((C59-C57)/(A59-A57))*(PI()/180) -> -3.041104 | K43: =(J44-J42)/(H44-H42) -> -24.076229
A44: 1.399 | B44: 161.5 | C44: -198.5 | H44: =A59 -> 1.899 | I44: =C59 -> -270.4 | J44: =((C60-C58)/(A60-A58))*(PI()/180) -> -4.7149939 | K44: =(J45-J43)/(H45-H43) -> -21.873021
...

Sheet Supuestos
A1: SUPUESTOS Y DATOS DEL MECANISMO (sin masa de tornillos)
A3: Parámetro | B3: Valor | D3: Cuerpo | E3: Masa (oz) | F3: Masa (kg) | G3: Peso (N) | H3: I_G (kg·m²)
A4: AB (m) | B4: 0.05 | D4: AB | E4: 0.1 | F4: =E4*$B$13 -> 0.00283495 | G4: =F4*$B$12 -> 0.02781086 | H4: =(1/12)*F4*$B$4^2 -> 5.9061458e-07
A5: BC (m) | B5: 0.1 | D5: BC | E5: 0.15 | F5: =E5*$B$13 -> 0.004252425 | G5: =F5*$B$12 -> 0.041716289 | H5: =(1/12)*F5*$B$5^2 -> 3.5436875e-06
A6: CD (m) | B6: 0.1 | D6: CDP | E6: 0.4 | F6: =E6*$B$13 -> 0.0113398 | G6: =F6*$B$12 -> 0.11124344 | H6: =0.000057823 -> 5.7823e-05
A7: DP (m) | B7: 0.115
A8: D_x (m) | B8: 0.0936
A9: D_y (m) | B9: 0.08499
A10: ω_AB constante (rad/s) | B10: -2.701947
A11: α_AB (rad/s²) | B11: 0
A12: g (m/s²) | B12: 9.81
A13: 1 oz en kg | B13: 0.0283495
A16: Nota
A17: No se considera la masa de los tornillos.
A18: AB rota alrededor del punto fijo A.
A19: BC tiene movimiento plano general.
A20: CDP rota alrededor del punto fijo D.
A21: M_A es un par puro aplicado por el servo.
A22: El peso solo entra en ΣF_y; no entra en ΣM_G porque se toma momento respecto al centro de masa.
A23: CG de CDP se toma desde C hacia P: CG = 121.28 mm; por tanto DG = 21.28 mm.
A24: Se usa r_G/D = -0.2128 r_C/D para CDP.

Sheet Cinematica
A1: CINEMÁTICA DEL MECANISMO
A2: t (s) | B2: θ_AB (°) | C2: θ_AB (rad) | D2: ω_AB | E2: α_AB | F2: x_B | G2: y_B | H2: BD=d | I2: x_M | J2: y_M | K2: h | L2: x_C | M2: y_C | N2: x_CB | O2: y_CB | P2: x_CD | Q2: y_CD | R2: x_PD | S2: y_PD | T2: v_Bx | U2: v_By | V2: v_B | W2: a_Bx | X2: a_By | Y2: a_B | Z2: ω_BC | AA2: ω_CD | AB2: α_BC | AC2: α_CD | AD2: v_Cx | AE2: v_Cy | AF2: v_C | AG2: a_Cx | AH2: a_Cy | AI2: a_C | AJ2: v_Px | AK2: v_Py | AL2: v_P | AM2: a_Px | AN2: a_Py | AO2: a_P | AP2: x_GAB | AQ2: y_GAB | AR2: a_GABx | AS2: a_GABy | AT2: x_GBC/B | AU2: y_GBC/B | AV2: a_GBCx | AW2: a_GBCy | AX2: x_GCDP/D | AY2: y_GCDP/D | AZ2: a_GCDPx | BA2: a_GCDPy | BB2: BC check | BC2: CD check | BD2: θ_BC (°) | BE2: θ_CD (°)
A3: 0.9 | B3: -145.3 | C3: =RADIANS(B3) -> -2.5359634 | D3: =Supuestos!$B$10 -> -2.701947 | E3: =Supuestos!$B$11 -> 0 | F3: =Supuestos!$B$4*COS(C3) -> -0.041107202 | G3: =Supuestos!$B$4*SIN(C3) -> -0.028463976 | H3: =SQRT((Supuestos!$B$8-F3)^2+(Supuestos!$B$9-G3)^2) -> 0.17611881 | I3: =(F3+Supuestos!$B$8)/2 -> 0.026246399 | J3: =(G3+Supuestos!$B$9)/2 -> 0.028263012 | K3: =SQRT(Supuestos!$B$5^2-(H3/2)^2) -> 0.047387142 | L3: =I3-K3*(Supuestos!$B$9-G3)/H3 -> -0.0042799243 | M3: =J3+K3*(Supuestos!$B$8-F3)/H3 -> 0.064507802 | N3: =L3-F3 -> 0.036827278 | O3: =M3-G3 -> 0.092971779 | P3: =L3-Supuestos!$B$8 -> -0.097879924 | Q3: =M3-Supuestos!$B$9 -> -0.020482198 | R3: =-(Supuestos!$B$7/Supuestos!$B$6)*P3 -> 0.11256191 | S3: =-(Supuestos!$B$7/Supuestos!$B$6)*Q3 -> 0.023554527 | T3: =D3*(-G3) -> -0.076908155 | U3: =D3*F3 -> 0.11106948 | V3: =SQRT(T3^2+U3^2) -> 0.13509735 | W3: =E3*(-G3)-D3^2*F3 -> 0.30010385 | X3: =E3*F3-D3^2*G3 -> 0.20780176 | Y3: =SQRT(W3^2+X3^2) -> 0.36502588 | Z3: =((-T3)*(-P3)-Q3*(-U3))/((-O3)*(-P3)-Q3*N3) -> -0.62939899 | AA3: =((-O3)*(-U3)-(-T3)*N3)/((-O3)*(-P3)-Q3*N3) -> -0.89794134 | AB3: =((-W3+Z3^2*N3-AA3^2*P3)*(-P3)-Q3*(-X3+Z3^2*O3-AA3^2*Q3))/((-O3)*(-P3)-Q3*N3) -> 2.802028 | AC3: =((-O3)*(-X3+Z3^2*O3-AA3^2*Q3)-(-W3+Z3^2*N3-AA3^2*P3)*N3)/((-O3)*(-P3)-Q3*N3) -> -2.6322857 | AD3: =AA3*(-Q3) -> -0.018391812 | AE3: =AA3*P3 -> 0.08789043 | AF3: =SQRT(AD3^2+AE3^2) -> 0.089794134 | AG3: =AC3*(-Q3)-AA3^2*P3 -> 0.025005454 | AH3: =AC3*P3-AA3^2*Q3 -> 0.27416269 | AI3: =SQRT(AG3^2+AH3^2) -> 0.27530066 | AJ3: =AA3*(-S3) -> 0.021150584 | AK3: =AA3*R3 -> -0.10107399 | AL3: =SQRT(AJ3^2+AK3^2) -> 0.10326325 | AM3: =AC3*(-S3)-AA3^2*R3 -> -0.028756272 | AN3: =AC3*R3-AA3^2*S3 -> -0.3152871 | AO3: =SQRT(AM3^2+AN3^2) -> 0.31659576 | AP3: =F3/2 -> -0.020553601 | AQ3: =G3/2 -> -0.014231988 | AR3: =E3*(-AQ3)-D3^2*AP3 -> 0.15005193 | AS3: =E3*AP3-D3^2*AQ3 -> 0.10390088 | AT3: =0.5*N3 -> 0.018413639 | AU3: =0.5*O3 -> 0.046485889 | AV3: =W3+AB3*(-AU3)-Z3^2*AT3 -> 0.16255465 | AW3: =X3+AB3*AT3-Z3^2*AU3 -> 0.24098223 | AX3: =-0.2128*P3 -> 0.020828848 | AY3: =-0.2128*Q3 -> 0.0043586116 | AZ3: =AC3*(-AY3)-AA3^2*AX3 -> -0.0053211606 | BA3: =AC3*AX3-AA3^2*AY3 -> -0.058341821 | BB3: =SQRT(N3^2+O3^2) -> 0.1 | BC3: =SQRT(P3^2+Q3^2) -> 0.1 | BD3: =DEGREES(ATAN2(N3,O3)) -> 68.390866 | BE3: =DEGREES(ATAN2(P3,Q3)) -> -168.18092
A4: 1.266 | B4: -185.3 | C4: =RADIANS(B4) -> -3.2340951 | D4: =Supuestos!$B$10 -> -2.701947 | E4: =Supuestos!$B$11 -> 0 | F4: =Supuestos!$B$4*COS(C4) -> -0.049786235 | G4: =Supuestos!$B$4*SIN(C4) -> 0.0046185294 | H4: =SQRT((Supuestos!$B$8-F4)^2+(Supuestos!$B$9-G4)^2) -> 0.16437514 | I4: =(F4+Supuestos!$B$8)/2 -> 0.021906883 | J4: =(G4+Supuestos!$B$9)/2 -> 0.044804265 | K4: =SQRT(Supuestos!$B$5^2-(H4/2)^2) -> 0.056966688 | L4: =I4-K4*(Supuestos!$B$9-G4)/H4 -> -0.0059470655 | M4: =J4+K4*(Supuestos!$B$8-F4)/H4 -> 0.094496932 | N4: =L4-F4 -> 0.043839169 | O4: =M4-G4 -> 0.089878402 | P4: =L4-Supuestos!$B$8 -> -0.099547065 | Q4: =M4-Supuestos!$B$9 -> 0.0095069318 | R4: =-(Supuestos!$B$7/Supuestos!$B$6)*P4 -> 0.11447913 | S4: =-(Supuestos!$B$7/Supuestos!$B$6)*Q4 -> -0.010932972 | T4: =D4*(-G4) -> 0.012479022 | U4: =D4*F4 -> 0.13451977 | V4: =SQRT(T4^2+U4^2) -> 0.13509735 | W4: =E4*(-G4)-D4^2*F4 -> 0.36346528 | X4: =E4*F4-D4^2*G4 -> -0.033717655 | Y4: =SQRT(W4^2+X4^2) -> 0.36502588 | Z4: =((-T4)*(-P4)-Q4*(-U4))/((-O4)*(-P4)-Q4*N4) -> -0.0039107909 | AA4: =((-O4)*(-U4)-(-T4)*N4)/((-O4)*(-P4)-Q4*N4) -> -1.349596 | AB4: =((-W4+Z4^2*N4-AA4^2*P4)*(-P4)-Q4*(-X4+Z4^2*O4-AA4^2*Q4))/((-O4)*(-P4)-Q4*N4) -> 1.9530636 | AC4: =((-O4)*(-X4+Z4^2*O4-AA4^2*Q4)-(-W4+Z4^2*N4-AA4^2*P4)*N4)/((-O4)*(-P4)-Q4*N4) -> -0.69532608 | AD4: =AA4*(-Q4) -> 0.012830517 | AE4: =AA4*P4 -> 0.13434832 | AF4: =SQRT(AD4^2+AE4^2) -> 0.1349596 | AG4: =AC4*(-Q4)-AA4^2*P4 -> 0.18792638 | AH4: =AC4*P4-AA4^2*Q4 -> 0.051901656 | AI4: =SQRT(AG4^2+AH4^2) -> 0.1949618 | AJ4: =AA4*(-S4) -> -0.014755095 | AK4: =AA4*R4 -> -0.15450057 | AL4: =SQRT(AJ4^2+AK4^2) -> 0.15520354 | AM4: =AC4*(-S4)-AA4^2*R4 -> -0.21611533 | AN4: =AC4*R4-AA4^2*S4 -> -0.059686905 | AO4: =SQRT(AM4^2+AN4^2) -> 0.22420607 | AP4: =F4/2 -> -0.024893117 | AQ4: =G4/2 -> 0.0023092647 | AR4: =E4*(-AQ4)-D4^2*AP4 -> 0.18173264 | AS4: =E4*AP4-D4^2*AQ4 -> -0.016858827 | AT4: =0.5*N4 -> 0.021919585 | AU4: =0.5*O4 -> 0.044939201 | AV4: =W4+AB4*(-AU4)-Z4^2*AT4 -> 0.27569583 | AW4: =X4+AB4*AT4-Z4^2*AU4 -> 0.0090920008 | AX4: =-0.2128*P4 -> 0.021183616 | AY4: =-0.2128*Q4 -> -0.0020230751 | AZ4: =AC4*(-AY4)-AA4^2*AX4 -> -0.039990733 | BA4: =AC4*AX4-AA4^2*AY4 -> -0.011044672 | BB4: =SQRT(N4^2+O4^2) -> 0.1 | BC4: =SQRT(P4^2+Q4^2) -> 0.1 | BD4: =DEGREES(ATAN2(N4,O4)) -> 63.99869 | BE4: =DEGREES(ATAN2(P4,Q4)) -> 174.54469
A5: 1.633 | B5: -226.8 | C5: =RADIANS(B5) -> -3.9584067 | D5: =Supuestos!$B$10 -> -2.701947 | E5: =Supuestos!$B$11 -> 0 | F5: =Supuestos!$B$4*COS(C5) -> -0.034227355 | G5: =Supuestos!$B$4*SIN(C5) -> 0.036448431 | H5: =SQRT((Supuestos!$B$8-F5)^2+(Supuestos!$B$9-G5)^2) -> 0.13673374 | I5: =(F5+Supuestos!$B$8)/2 -> 0.029686322 | J5: =(G5+Supuestos!$B$9)/2 -> 0.060719216 | K5: =SQRT(Supuestos!$B$5^2-(H5/2)^2) -> 0.072979249 | L5: =I5-K5*(Supuestos!$B$9-G5)/H5 -> 0.0037781072 | M5: =J5+K5*(Supuestos!$B$8-F5)/H5 -> 0.12894484 | N5: =L5-F5 -> 0.038005463 | O5: =M5-G5 -> 0.092496404 | P5: =L5-Supuestos!$B$8 -> -0.089821893 | Q5: =M5-Supuestos!$B$9 -> 0.043954836 | R5: =-(Supuestos!$B$7/Supuestos!$B$6)*P5 -> 0.10329518 | S5: =-(Supuestos!$B$7/Supuestos!$B$6)*Q5 -> -0.050548061 | T5: =D5*(-G5) -> 0.09848173 | U5: =D5*F5 -> 0.0924805 | V5: =SQRT(T5^2+U5^2) -> 0.13509735 | W5: =E5*(-G5)-D5^2*F5 -> 0.24987741 | X5: =E5*F5-D5^2*G5 -> -0.26609241 | Y5: =SQRT(W5^2+X5^2) -> 0.36502588 | Z5: =((-T5)*(-P5)-Q5*(-U5))/((-O5)*(-P5)-Q5*N5) -> 0.47910427 | AA5: =((-O5)*(-U5)-(-T5)*N5)/((-O5)*(-P5)-Q5*N5) -> -1.2323174 | AB5: =((-W5+Z5^2*N5-AA5^2*P5)*(-P5)-Q5*(-X5+Z5^2*O5-AA5^2*Q5))/((-O5)*(-P5)-Q5*N5) -> 1.9144825 | AC5: =((-O5)*(-X5+Z5^2*O5-AA5^2*Q5)-(-W5+Z5^2*N5-AA5^2*P5)*N5)/((-O5)*(-P5)-Q5*N5) -> 1.645626 | AD5: =AA5*(-Q5) -> 0.054166308 | AE5: =AA5*P5 -> 0.11068908 | AF5: =SQRT(AD5^2+AE5^2) -> 0.12323174 | AG5: =AC5*(-Q5)-AA5^2*P5 -> 0.064070853 | AH5: =AC5*P5-AA5^2*Q5 -> -0.21456333 | AI5: =SQRT(AG5^2+AH5^2) -> 0.2239252 | AJ5: =AA5*(-S5) -> -0.062291254 | AK5: =AA5*R5 -> -0.12729244 | AL5: =SQRT(AJ5^2+AK5^2) -> 0.1417165 | AM5: =AC5*(-S5)-AA5^2*R5 -> -0.073681481 | AN5: =AC5*R5-AA5^2*S5 -> 0.24674783 | AO5: =SQRT(AM5^2+AN5^2) -> 0.25751398 | AP5: =F5/2 -> -0.017113678 | AQ5: =G5/2 -> 0.018224216 | AR5: =E5*(-AQ5)-D5^2*AP5 -> 0.1249387 | AS5: =E5*AP5-D5^2*AQ5 -> -0.13304621 | AT5: =0.5*N5 -> 0.019002731 | AU5: =0.5*O5 -> 0.046248202 | AV5: =W5+AB5*(-AU5)-Z5^2*AT5 -> 0.15697413 | AW5: =X5+AB5*AT5-Z5^2*AU5 -> -0.24032787 | AX5: =-0.2128*P5 -> 0.019114099 | AY5: =-0.2128*Q5 -> -0.009353589 | AZ5: =AC5*(-AY5)-AA5^2*AX5 -> -0.013634278 | BA5: =AC5*AX5-AA5^2*AY5 -> 0.045659076 | BB5: =SQRT(N5^2+O5^2) -> 0.1 | BC5: =SQRT(P5^2+Q5^2) -> 0.1 | BD5: =DEGREES(ATAN2(N5,O5)) -> 67.662934 | BE5: =DEGREES(ATAN2(P5,Q5)) -> 153.92493
A6: 1.766 | B6: -246.9 | C6: =RADIANS(B6) -> -4.3092179 | D6: =Supuestos!$B$10 -> -2.701947 | E6: =Supuestos!$B$11 -> 0 | F6: =Supuestos!$B$4*COS(C6) -> -0.019616856 | G6: =Supuestos!$B$4*SIN(C6) -> 0.045991075 | H6: =SQRT((Supuestos!$B$8-F6)^2+(Supuestos!$B$9-G6)^2) -> 0.11974545 | I6: =(F6+Supuestos!$B$8)/2 -> 0.036991572 | J6: =(G6+Supuestos!$B$9)/2 -> 0.065490537 | K6: =SQRT(Supuestos!$B$5^2-(H6/2)^2) -> 0.080095299 | L6: =I6-K6*(Supuestos!$B$9-G6)/H6 -> 0.010905983 | M6: =J6+K6*(Supuestos!$B$8-F6)/H6 -> 0.14121899 | N6: =L6-F6 -> 0.030522839 | O6: =M6-G6 -> 0.095227918 | P6: =L6-Supuestos!$B$8 -> -0.082694017 | Q6: =M6-Supuestos!$B$9 -> 0.056228992 | R6: =-(Supuestos!$B$7/Supuestos!$B$6)*P6 -> 0.095098119 | S6: =-(Supuestos!$B$7/Supuestos!$B$6)*Q6 -> -0.064663341 | T6: =D6*(-G6) -> 0.12426545 | U6: =D6*F6 -> 0.053003705 | V6: =SQRT(T6^2+U6^2) -> 0.13509735 | W6: =E6*(-G6)-D6^2*F6 -> 0.1432132 | X6: =E6*F6-D6^2*G6 -> -0.33575865 | Y6: =SQRT(W6^2+X6^2) -> 0.36502588 | Z6: =((-T6)*(-P6)-Q6*(-U6))/((-O6)*(-P6)-Q6*N6) -> 0.76067437 | AA6: =((-O6)*(-U6)-(-T6)*N6)/((-O6)*(-P6)-Q6*N6) -> -0.92173109 | AB6: =((-W6+Z6^2*N6-AA6^2*P6)*(-P6)-Q6*(-X6+Z6^2*O6-AA6^2*Q6))/((-O6)*(-P6)-Q6*N6) -> 2.4881715 | AC6: =((-O6)*(-X6+Z6^2*O6-AA6^2*Q6)-(-W6+Z6^2*N6-AA6^2*P6)*N6)/((-O6)*(-P6)-Q6*N6) -> 3.2304926 | AD6: =AA6*(-Q6) -> 0.051828011 | AE6: =AA6*P6 -> 0.076221646 | AF6: =SQRT(AD6^2+AE6^2) -> 0.092173109 | AG6: =AC6*(-Q6)-AA6^2*P6 -> -0.11139148 | AH6: =AC6*P6-AA6^2*Q6 -> -0.31491389 | AI6: =SQRT(AG6^2+AH6^2) -> 0.33403416 | AJ6: =AA6*(-S6) -> -0.059602212 | AK6: =AA6*R6 -> -0.087654893 | AL6: =SQRT(AJ6^2+AK6^2) -> 0.10599908 | AM6: =AC6*(-S6)-AA6^2*R6 -> 0.1281002 | AN6: =AC6*R6-AA6^2*S6 -> 0.36215098 | AO6: =SQRT(AM6^2+AN6^2) -> 0.38413929 | AP6: =F6/2 -> -0.0098084279 | AQ6: =G6/2 -> 0.022995537 | AR6: =E6*(-AQ6)-D6^2*AP6 -> 0.071606601 | AS6: =E6*AP6-D6^2*AQ6 -> -0.16787933 | AT6: =0.5*N6 -> 0.01526142 | AU6: =0.5*O6 -> 0.047613959 | AV6: =W6+AB6*(-AU6)-Z6^2*AT6 -> 0.01591086 | AW6: =X6+AB6*AT6-Z6^2*AU6 -> -0.32533627 | AX6: =-0.2128*P6 -> 0.017597287 | AY6: =-0.2128*Q6 -> -0.01196553 | AZ6: =AC6*(-AY6)-AA6^2*AX6 -> 0.023704107 | BA6: =AC6*AX6-AA6^2*AY6 -> 0.067013677 | BB6: =SQRT(N6^2+O6^2) -> 0.1 | BC6: =SQRT(P6^2+Q6^2) -> 0.1 | BD6: =DEGREES(ATAN2(N6,O6)) -> 72.228095 | BE6: =DEGREES(ATAN2(P6,Q6)) -> 145.78569
A7: 1.899 | B7: -270.4 | C7: =RADIANS(B7) -> -4.7193703 | D7: =Supuestos!$B$10 -> -2.701947 | E7: =Supuestos!$B$11 -> 0 | F7: =Supuestos!$B$4*COS(C7) -> 0.00034906301 | G7: =Supuestos!$B$4*SIN(C7) -> 0.049998782 | H7: =SQRT((Supuestos!$B$8-F7)^2+(Supuestos!$B$9-G7)^2) -> 0.099599812 | I7: =(F7+Supuestos!$B$8)/2 -> 0.046974532 | J7: =(G7+Supuestos!$B$9)/2 -> 0.067494391 | K7: =SQRT(Supuestos!$B$5^2-(H7/2)^2) -> 0.086717757 | L7: =I7-K7*(Supuestos!$B$9-G7)/H7 -> 0.016509013 | M7: =J7+K7*(Supuestos!$B$8-F7)/H7 -> 0.14868442 | N7: =L7-F7 -> 0.01615995 | O7: =M7-G7 -> 0.098685642 | P7: =L7-Supuestos!$B$8 -> -0.077090987 | Q7: =M7-Supuestos!$B$9 -> 0.063694424 | R7: =-(Supuestos!$B$7/Supuestos!$B$6)*P7 -> 0.088654636 | S7: =-(Supuestos!$B$7/Supuestos!$B$6)*Q7 -> -0.073248588 | T7: =D7*(-G7) -> 0.13509406 | U7: =D7*F7 -> -0.00094314977 | V7: =SQRT(T7^2+U7^2) -> 0.13509735 | W7: =E7*(-G7)-D7^2*F7 -> -0.0025483407 | X7: =E7*F7-D7^2*G7 -> -0.36501698 | Y7: =SQRT(W7^2+X7^2) -> 0.36502588 | Z7: =((-T7)*(-P7)-Q7*(-U7))/((-O7)*(-P7)-Q7*N7) -> 1.2127498 | AA7: =((-O7)*(-U7)-(-T7)*N7)/((-O7)*(-P7)-Q7*N7) -> -0.24198452 | AB7: =((-W7+Z7^2*N7-AA7^2*P7)*(-P7)-Q7*(-X7+Z7^2*O7-AA7^2*Q7))/((-O7)*(-P7)-Q7*N7) -> 3.4595146 | AC7: =((-O7)*(-X7+Z7^2*O7-AA7^2*Q7)-(-W7+Z7^2*N7-AA7^2*P7)*N7)/((-O7)*(-P7)-Q7*N7) -> 5.8440655 | AD7: =AA7*(-Q7) -> 0.015413065 | AE7: =AA7*P7 -> 0.018654826 | AF7: =SQRT(AD7^2+AE7^2) -> 0.024198452 | AG7: =AC7*(-Q7)-AA7^2*P7 -> -0.36772021 | AH7: =AC7*P7-AA7^2*Q7 -> -0.4542545 | AI7: =SQRT(AG7^2+AH7^2) -> 0.58443588 | AJ7: =AA7*(-S7) -> -0.017725024 | AK7: =AA7*R7 -> -0.02145305 | AL7: =SQRT(AJ7^2+AK7^2) -> 0.02782822 | AM7: =AC7*(-S7)-AA7^2*R7 -> 0.42287824 | AN7: =AC7*R7-AA7^2*S7 -> 0.52239268 | AO7: =SQRT(AM7^2+AN7^2) -> 0.67210127 | AP7: =F7/2 -> 0.00017453151 | AQ7: =G7/2 -> 0.024999391 | AR7: =E7*(-AQ7)-D7^2*AP7 -> -0.0012741703 | AS7: =E7*AP7-D7^2*AQ7 -> -0.18250849 | AT7: =0.5*N7 -> 0.0080799748 | AU7: =0.5*O7 -> 0.049342821 | AV7: =W7+AB7*(-AU7)-Z7^2*AT7 -> -0.18513427 | AW7: =X7+AB7*AT7-Z7^2*AU7 -> -0.40963574 | AX7: =-0.2128*P7 -> 0.016404962 | AY7: =-0.2128*Q7 -> -0.013554173 | AZ7: =AC7*(-AY7)-AA7^2*AX7 -> 0.07825086 | BA7: =AC7*AX7-AA7^2*AY7 -> 0.096665358 | BB7: =SQRT(N7^2+O7^2) -> 0.1 | BC7: =SQRT(P7^2+Q7^2) -> 0.1 | BD7: =DEGREES(ATAN2(N7,O7)) -> 80.700251 | BE7: =DEGREES(ATAN2(P7,Q7)) -> 140.43567
A8: 2.099 | B8: -316.4 | C8: =RADIANS(B8) -> -5.5222218 | D8: =Supuestos!$B$10 -> -2.701947 | E8: =Supuestos!$B$11 -> 0 | F8: =Supuestos!$B$4*COS(C8) -> 0.036208593 | G8: =Supuestos!$B$4*SIN(C8) -> 0.034480977 | H8: =SQRT((Supuestos!$B$8-F8)^2+(Supuestos!$B$9-G8)^2) -> 0.076452174 | I8: =(F8+Supuestos!$B$8)/2 -> 0.064904297 | J8: =(G8+Supuestos!$B$9)/2 -> 0.059735489 | K8: =SQRT(Supuestos!$B$5^2-(H8/2)^2) -> 0.092405445 | L8: =I8-K8*(Supuestos!$B$9-G8)/H8 -> 0.003855559 | M8: =J8+K8*(Supuestos!$B$8-F8)/H8 -> 0.12910276 | N8: =L8-F8 -> -0.032353034 | O8: =M8-G8 -> 0.09462178 | P8: =L8-Supuestos!$B$8 -> -0.089744441 | Q8: =M8-Supuestos!$B$9 -> 0.044112757 | R8: =-(Supuestos!$B$7/Supuestos!$B$6)*P8 -> 0.10320611 | S8: =-(Supuestos!$B$7/Supuestos!$B$6)*Q8 -> -0.05072967 | T8: =D8*(-G8) -> 0.093165773 | U8: =D8*F8 -> -0.097833699 | V8: =SQRT(T8^2+U8^2) -> 0.13509735 | W8: =E8*(-G8)-D8^2*F8 -> -0.26434147 | X8: =E8*F8-D8^2*G8 -> -0.25172898 | Y8: =SQRT(W8^2+X8^2) -> 0.36502588 | Z8: =((-T8)*(-P8)-Q8*(-U8))/((-O8)*(-P8)-Q8*N8) -> 1.7944157 | AA8: =((-O8)*(-U8)-(-T8)*N8)/((-O8)*(-P8)-Q8*N8) -> 1.7370267 | AB8: =((-W8+Z8^2*N8-AA8^2*P8)*(-P8)-Q8*(-X8+Z8^2*O8-AA8^2*Q8))/((-O8)*(-P8)-Q8*N8) -> -2.8313281 | AC8: =((-O8)*(-X8+Z8^2*O8-AA8^2*Q8)-(-W8+Z8^2*N8-AA8^2*P8)*N8)/((-O8)*(-P8)-Q8*N8) -> 3.6960784 | AD8: =AA8*(-Q8) -> -0.076625038 | AE8: =AA8*P8 -> -0.15588849 | AF8: =SQRT(AD8^2+AE8^2) -> 0.17370267 | AG8: =AC8*(-Q8)-AA8^2*P8 -> 0.10773827 | AH8: =AC8*P8-AA8^2*Q8 -> -0.46480223 | AI8: =SQRT(AG8^2+AH8^2) -> 0.4771254 | AJ8: =AA8*(-S8) -> 0.088118794 | AK8: =AA8*R8 -> 0.17927177 | AL8: =SQRT(AJ8^2+AK8^2) -> 0.19975807 | AM8: =AC8*(-S8)-AA8^2*R8 -> -0.12389901 | AN8: =AC8*R8-AA8^2*S8 -> 0.53452256 | AO8: =SQRT(AM8^2+AN8^2) -> 0.54869421 | AP8: =F8/2 -> 0.018104297 | AQ8: =G8/2 -> 0.017240489 | AR8: =E8*(-AQ8)-D8^2*AP8 -> -0.13217074 | AS8: =E8*AP8-D8^2*AQ8 -> -0.12586449 | AT8: =0.5*N8 -> -0.016176517 | AU8: =0.5*O8 -> 0.04731089 | AV8: =W8+AB8*(-AU8)-Z8^2*AT8 -> -0.078301599 | AW8: =X8+AB8*AT8-Z8^2*AU8 -> -0.3582656 | AX8: =-0.2128*P8 -> 0.019097617 | AY8: =-0.2128*Q8 -> -0.0093871947 | AZ8: =AC8*(-AY8)-AA8^2*AX8 -> -0.022926704 | BA8: =AC8*AX8-AA8^2*AY8 -> 0.098909914 | BB8: =SQRT(N8^2+O8^2) -> 0.1 | BC8: =SQRT(P8^2+Q8^2) -> 0.1 | BD8: =DEGREES(ATAN2(N8,O8)) -> 108.87656 | BE8: =DEGREES(ATAN2(P8,Q8)) -> 153.82415

Sheet Resumen
A1: RESUMEN CINEMÁTICO
A3: t (s) | B3: θ_AB (°) | C3: ω_BC | D3: ω_CD | E3: α_BC | F3: α_CD | G3: v_A | H3: a_A | I3: v_B | J3: a_B | K3: v_C | L3: a_C | M3: v_D | N3: a_D | O3: v_P | P3: a_P | Q3: Comentario
A4: =Cinematica!A3 -> 0.9 | B4: =Cinematica!B3 -> -145.3 | C4: =Cinematica!Z3 -> -0.62939899 | D4: =Cinematica!AA3 -> -0.89794134 | E4: =Cinematica!AB3 -> 2.802028 | F4: =Cinematica!AC3 -> -2.6322857 | G4: =0 -> 0 | H4: =0 -> 0 | I4: =Cinematica!V3 -> 0.13509735 | J4: =Cinematica!Y3 -> 0.36502588 | K4: =Cinematica!AF3 -> 0.089794134 | L4: =Cinematica!AI3 -> 0.27530066 | M4: =0 -> 0 | N4: =0 -> 0 | O4: =Cinematica!AL3 -> 0.10326325 | P4: =Cinematica!AO3 -> 0.31659576 | Q4: =IF(ABS(Cinematica!BB3-Supuestos!$B$5)<0.000000001,"OK","Revisar") -> OK
A5: =Cinematica!A4 -> 1.266 | B5: =Cinematica!B4 -> -185.3 | C5: =Cinematica!Z4 -> -0.0039107909 | D5: =Cinematica!AA4 -> -1.349596 | E5: =Cinematica!AB4 -> 1.9530636 | F5: =Cinematica!AC4 -> -0.69532608 | G5: =0 -> 0 | H5: =0 -> 0 | I5: =Cinematica!V4 -> 0.13509735 | J5: =Cinematica!Y4 -> 0.36502588 | K5: =Cinematica!AF4 -> 0.1349596 | L5: =Cinematica!AI4 -> 0.1949618 | M5: =0 -> 0 | N5: =0 -> 0 | O5: =Cinematica!AL4 -> 0.15520354 | P5: =Cinematica!AO4 -> 0.22420607 | Q5: =IF(ABS(Cinematica!BB4-Supuestos!$B$5)<0.000000001,"OK","Revisar") -> OK
A6: =Cinematica!A5 -> 1.633 | B6: =Cinematica!B5 -> -226.8 | C6: =Cinematica!Z5 -> 0.47910427 | D6: =Cinematica!AA5 -> -1.2323174 | E6: =Cinematica!AB5 -> 1.9144825 | F6: =Cinematica!AC5 -> 1.645626 | G6: =0 -> 0 | H6: =0 -> 0 | I6: =Cinematica!V5 -> 0.13509735 | J6: =Cinematica!Y5 -> 0.36502588 | K6: =Cinematica!AF5 -> 0.12323174 | L6: =Cinematica!AI5 -> 0.2239252 | M6: =0 -> 0 | N6: =0 -> 0 | O6: =Cinematica!AL5 -> 0.1417165 | P6: =Cinematica!AO5 -> 0.25751398 | Q6: =IF(ABS(Cinematica!BB5-Supuestos!$B$5)<0.000000001,"OK","Revisar") -> OK
A7: =Cinematica!A6 -> 1.766 | B7: =Cinematica!B6 -> -246.9 | C7: =Cinematica!Z6 -> 0.76067437 | D7: =Cinematica!AA6 -> -0.92173109 | E7: =Cinematica!AB6 -> 2.4881715 | F7: =Cinematica!AC6 -> 3.2304926 | G7: =0 -> 0 | H7: =0 -> 0 | I7: =Cinematica!V6 -> 0.13509735 | J7: =Cinematica!Y6 -> 0.36502588 | K7: =Cinematica!AF6 -> 0.092173109 | L7: =Cinematica!AI6 -> 0.33403416 | M7: =0 -> 0 | N7: =0 -> 0 | O7: =Cinematica!AL6 -> 0.10599908 | P7: =Cinematica!AO6 -> 0.38413929 | Q7: =IF(ABS(Cinematica!BB6-Supuestos!$B$5)<0.000000001,"OK","Revisar") -> OK
A8: =Cinematica!A7 -> 1.899 | B8: =Cinematica!B7 -> -270.4 | C8: =Cinematica!Z7 -> 1.2127498 | D8: =Cinematica!AA7 -> -0.24198452 | E8: =Cinematica!AB7 -> 3.4595146 | F8: =Cinematica!AC7 -> 5.8440655 | G8: =0 -> 0 | H8: =0 -> 0 | I8: =Cinematica!V7 -> 0.13509735 | J8: =Cinematica!Y7 -> 0.36502588 | K8: =Cinematica!AF7 -> 0.024198452 | L8: =Cinematica!AI7 -> 0.58443588 | M8: =0 -> 0 | N8: =0 -> 0 | O8: =Cinematica!AL7 -> 0.02782822 | P8: =Cinematica!AO7 -> 0.67210127 | Q8: =IF(ABS(Cinematica!BB7-Supuestos!$B$5)<0.000000001,"OK","Revisar") -> OK
A9: =Cinematica!A8 -> 2.099 | B9: =Cinematica!B8 -> -316.4 | C9: =Cinematica!Z8 -> 1.7944157 | D9: =Cinematica!AA8 -> 1.7370267 | E9: =Cinematica!AB8 -> -2.8313281 | F9: =Cinematica!AC8 -> 3.6960784 | G9: =0 -> 0 | H9: =0 -> 0 | I9: =Cinematica!V8 -> 0.13509735 | J9: =Cinematica!Y8 -> 0.36502588 | K9: =Cinematica!AF8 -> 0.17370267 | L9: =Cinematica!AI8 -> 0.4771254 | M9: =0 -> 0 | N9: =0 -> 0 | O9: =Cinematica!AL8 -> 0.19975807 | P9: =Cinematica!AO8 -> 0.54869421 | Q9: =IF(ABS(Cinematica!BB8-Supuestos!$B$5)<0.000000001,"OK","Revisar") -> OK

Sheet Sistema Reacciones
A1: SISTEMA DE ECUACIONES DE REACCIONES (sin masa de tornillos)
A3: ="Posición 1 t="&TEXT(Cinematica!A3,"0.000")&" s θ_AB="&TEXT(Cinematica!B3,"0.0")&"°" -> Posición 1 t=0.900 s θ_AB=-145.3°
A4: Ecuación | B4: Ax | C4: Ay | D4: Bx | E4: By | F4: Cx | G4: Cy | H4: Dx | I4: Dy | J4: M_A | K4: RHS | L4: Residual
A5: AB ΣFx | B5: =1 -> 1 | C5: =0 -> 0 | D5: =1 -> 1 | E5: =0 -> 0 | F5: =0 -> 0 | G5: =0 -> 0 | H5: =0 -> 0 | I5: =0 -> 0 | J5: =0 -> 0 | K5: =Supuestos!$F$4*Cinematica!AR3 -> 0.00042538971 | L5: =SUMPRODUCT(B5:J5,Reacciones!$B$4:$J$4)-K5 -> 7.0473141e-19
A6: AB ΣFy | B6: =0 -> 0 | C6: =1 -> 1 | D6: =0 -> 0 | E6: =1 -> 1 | F6: =0 -> 0 | G6: =0 -> 0 | H6: =0 -> 0 | I6: =0 -> 0 | J6: =0 -> 0 | K6: =Supuestos!$F$4*Cinematica!AS3+Supuestos!$G$4 -> 0.028105413 | L6: =SUMPRODUCT(B6:J6,Reacciones!$B$4:$J$4)-K6 -> 0
A7: AB ΣM_G | B7: =Cinematica!AQ3 -> -0.014231988 | C7: =-Cinematica!AP3 -> 0.020553601 | D7: =-(Cinematica!G3-Cinematica!AQ3) -> 0.014231988 | E7: =Cinematica!F3-Cinematica!AP3 -> -0.020553601 | F7: =0 -> 0 | G7: =0 -> 0 | H7: =0 -> 0 | I7: =0 -> 0 | J7: =1 -> 1 | K7: =Supuestos!$H$4*Cinematica!E3 -> 0 | L7: =SUMPRODUCT(B7:J7,Reacciones!$B$4:$J$4)-K7 -> 8.6736174e-19
A8: BC ΣFx | B8: =0 -> 0 | C8: =0 -> 0 | D8: =-1 -> -1 | E8: =0 -> 0 | F8: =1 -> 1 | G8: =0 -> 0 | H8: =0 -> 0 | I8: =0 -> 0 | J8: =0 -> 0 | K8: =Supuestos!$F$5*Cinematica!AV3 -> 0.00069125147 | L8: =SUMPRODUCT(B8:J8,Reacciones!$B$4:$J$4)-K8 -> -1.1926224e-18
A9: BC ΣFy | B9: =0 -> 0 | C9: =0 -> 0 | D9: =0 -> 0 | E9: =-1 -> -1 | F9: =0 -> 0 | G9: =1 -> 1 | H9: =0 -> 0 | I9: =0 -> 0 | J9: =0 -> 0 | K9: =Supuestos!$F$5*Cinematica!AW3+Supuestos!$G$5 -> 0.042741048 | L9: =SUMPRODUCT(B9:J9,Reacciones!$B$4:$J$4)-K9 -> 0
A10: BC ΣM_G | B10: =0 -> 0 | C10: =0 -> 0 | D10: =-Cinematica!AU3 -> -0.046485889 | E10: =Cinematica!AT3 -> 0.018413639 | F10: =-(Cinematica!O3-Cinematica!AU3) -> -0.046485889 | G10: =Cinematica!N3-Cinematica!AT3 -> 0.018413639 | H10: =0 -> 0 | I10: =0 -> 0 | J10: =0 -> 0 | K10: =Supuestos!$H$5*Cinematica!AB3 -> 9.9295116e-06 | L10: =SUMPRODUCT(B10:J10,Reacciones!$B$4:$J$4)-K10 -> 2.3886329e-19
A11: CDP ΣFx | B11: =0 -> 0 | C11: =0 -> 0 | D11: =0 -> 0 | E11: =0 -> 0 | F11: =-1 -> -1 | G11: =0 -> 0 | H11: =1 -> 1 | I11: =0 -> 0 | J11: =0 -> 0 | K11: =Supuestos!$F$6*Cinematica!AZ3 -> -6.0340897e-05 | L11: =SUMPRODUCT(B11:J11,Reacciones!$B$4:$J$4)-K11 -> 9.1479558e-19
A12: CDP ΣFy | B12: =0 -> 0 | C12: =0 -> 0 | D12: =0 -> 0 | E12: =0 -> 0 | F12: =0 -> 0 | G12: =-1 -> -1 | H12: =0 -> 0 | I12: =1 -> 1 | J12: =0 -> 0 | K12: =Supuestos!$F$6*Cinematica!BA3+Supuestos!$G$6 -> 0.11058185 | L12: =SUMPRODUCT(B12:J12,Reacciones!$B$4:$J$4)-K12 -> 0
A13: CDP ΣM_G | B13: =0 -> 0 | C13: =0 -> 0 | D13: =0 -> 0 | E13: =0 -> 0 | F13: =Cinematica!Q3-Cinematica!AY3 -> -0.024840809 | G13: =-(Cinematica!P3-Cinematica!AX3) -> 0.11870877 | H13: =Cinematica!AY3 -> 0.0043586116 | I13: =-Cinematica!AX3 -> -0.020828848 | J13: =0 -> 0 | K13: =Supuestos!$H$6*Cinematica!AC3 -> -0.00015220666 | L13: =SUMPRODUCT(B13:J13,Reacciones!$B$4:$J$4)-K13 -> -8.6736174e-19
A14: Soluciones (se muestran en hoja Reacciones)
A17: ="Posición 2 t="&TEXT(Cinematica!A4,"0.000")&" s θ_AB="&TEXT(Cinematica!B4,"0.0")&"°" -> Posición 2 t=1.266 s θ_AB=-185.3°
A18: Ecuación | B18: Ax | C18: Ay | D18: Bx | E18: By | F18: Cx | G18: Cy | H18: Dx | I18: Dy | J18: M_A | K18: RHS | L18: Residual
A19: AB ΣFx | B19: =1 -> 1 | C19: =0 -> 0 | D19: =1 -> 1 | E19: =0 -> 0 | F19: =0 -> 0 | G19: =0 -> 0 | H19: =0 -> 0 | I19: =0 -> 0 | J19: =0 -> 0 | K19: =Supuestos!$F$4*Cinematica!AR4 -> 0.00051520295 | L19: =SUMPRODUCT(B19:J19,Reacciones!$B$5:$J$5)-K19 -> -1.0842022e-18
A20: AB ΣFy | B20: =0 -> 0 | C20: =1 -> 1 | D20: =0 -> 0 | E20: =1 -> 1 | F20: =0 -> 0 | G20: =0 -> 0 | H20: =0 -> 0 | I20: =0 -> 0 | J20: =0 -> 0 | K20: =Supuestos!$F$4*Cinematica!AS4+Supuestos!$G$4 -> 0.027763066 | L20: =SUMPRODUCT(B20:J20,Reacciones!$B$5:$J$5)-K20 -> 0
A21: AB ΣM_G | B21: =Cinematica!AQ4 -> 0.0023092647 | C21: =-Cinematica!AP4 -> 0.024893117 | D21: =-(Cinematica!G4-Cinematica!AQ4) -> -0.0023092647 | E21: =Cinematica!F4-Cinematica!AP4 -> -0.024893117 | F21: =0 -> 0 | G21: =0 -> 0 | H21: =0 -> 0 | I21: =0 -> 0 | J21: =1 -> 1 | K21: =Supuestos!$H$4*Cinematica!E4 -> 0 | L21: =SUMPRODUCT(B21:J21,Reacciones!$B$5:$J$5)-K21 -> -1.0842022e-18
A22: BC ΣFx | B22: =0 -> 0 | C22: =0 -> 0 | D22: =-1 -> -1 | E22: =0 -> 0 | F22: =1 -> 1 | G22: =0 -> 0 | H22: =0 -> 0 | I22: =0 -> 0 | J22: =0 -> 0 | K22: =Supuestos!$F$5*Cinematica!AV4 -> 0.0011723758 | L22: =SUMPRODUCT(B22:J22,Reacciones!$B$5:$J$5)-K22 -> 0
A23: BC ΣFy | B23: =0 -> 0 | C23: =0 -> 0 | D23: =0 -> 0 | E23: =-1 -> -1 | F23: =0 -> 0 | G23: =1 -> 1 | H23: =0 -> 0 | I23: =0 -> 0 | J23: =0 -> 0 | K23: =Supuestos!$F$5*Cinematica!AW4+Supuestos!$G$5 -> 0.041754952 | L23: =SUMPRODUCT(B23:J23,Reacciones!$B$5:$J$5)-K23 -> 0
A24: BC ΣM_G | B24: =0 -> 0 | C24: =0 -> 0 | D24: =-Cinematica!AU4 -> -0.044939201 | E24: =Cinematica!AT4 -> 0.021919585 | F24: =-(Cinematica!O4-Cinematica!AU4) -> -0.044939201 | G24: =Cinematica!N4-Cinematica!AT4 -> 0.021919585 | H24: =0 -> 0 | I24: =0 -> 0 | J24: =0 -> 0 | K24: =Supuestos!$H$5*Cinematica!AB4 -> 6.9210471e-06 | L24: =SUMPRODUCT(B24:J24,Reacciones!$B$5:$J$5)-K24 -> 7.9621097e-20
A25: CDP ΣFx | B25: =0 -> 0 | C25: =0 -> 0 | D25: =0 -> 0 | E25: =0 -> 0 | F25: =-1 -> -1 | G25: =0 -> 0 | H25: =1 -> 1 | I25: =0 -> 0 | J25: =0 -> 0 | K25: =Supuestos!$F$6*Cinematica!AZ4 -> -0.00045348691 | L25: =SUMPRODUCT(B25:J25,Reacciones!$B$5:$J$5)-K25 -> 0
A26: CDP ΣFy | B26: =0 -> 0 | C26: =0 -> 0 | D26: =0 -> 0 | E26: =0 -> 0 | F26: =0 -> 0 | G26: =-1 -> -1 | H26: =0 -> 0 | I26: =1 -> 1 | J26: =0 -> 0 | K26: =Supuestos!$F$6*Cinematica!BA4+Supuestos!$G$6 -> 0.11111819 | L26: =SUMPRODUCT(B26:J26,Reacciones!$B$5:$J$5)-K26 -> 0
A27: CDP ΣM_G | B27: =0 -> 0 | C27: =0 -> 0 | D27: =0 -> 0 | E27: =0 -> 0 | F27: =Cinematica!Q4-Cinematica!AY4 -> 0.011530007 | G27: =-(Cinematica!P4-Cinematica!AX4) -> 0.12073068 | H27: =Cinematica!AY4 -> -0.0020230751 | I27: =-Cinematica!AX4 -> -0.021183616 | J27: =0 -> 0 | K27: =Supuestos!$H$6*Cinematica!AC4 -> -4.020584e-05 | L27: =SUMPRODUCT(B27:J27,Reacciones!$B$5:$J$5)-K27 -> -2.7647155e-18
A28: Soluciones (se muestran en hoja Reacciones)
A31: ="Posición 3 t="&TEXT(Cinematica!A5,"0.000")&" s θ_AB="&TEXT(Cinematica!B5,"0.0")&"°" -> Posición 3 t=1.633 s θ_AB=-226.8°
A32: Ecuación | B32: Ax | C32: Ay | D32: Bx | E32: By | F32: Cx | G32: Cy | H32: Dx | I32: Dy | J32: M_A | K32: RHS | L32: Residual
A33: AB ΣFx | B33: =1 -> 1 | C33: =0 -> 0 | D33: =1 -> 1 | E33: =0 -> 0 | F33: =0 -> 0 | G33: =0 -> 0 | H33: =0 -> 0 | I33: =0 -> 0 | J33: =0 -> 0 | K33: =Supuestos!$F$4*Cinematica!AR5 -> 0.00035419498 | L33: =SUMPRODUCT(B33:J33,Reacciones!$B$6:$J$6)-K33 -> 0
A34: AB ΣFy | B34: =0 -> 0 | C34: =1 -> 1 | D34: =0 -> 0 | E34: =1 -> 1 | F34: =0 -> 0 | G34: =0 -> 0 | H34: =0 -> 0 | I34: =0 -> 0 | J34: =0 -> 0 | K34: =Supuestos!$F$4*Cinematica!AS5+Supuestos!$G$4 -> 0.02743368 | L34: =SUMPRODUCT(B34:J34,Reacciones!$B$6:$J$6)-K34 -> 0
A35: AB ΣM_G | B35: =Cinematica!AQ5 -> 0.018224216 | C35: =-Cinematica!AP5 -> 0.017113678 | D35: =-(Cinematica!G5-Cinematica!AQ5) -> -0.018224216 | E35: =Cinematica!F5-Cinematica!AP5 -> -0.017113678 | F35: =0 -> 0 | G35: =0 -> 0 | H35: =0 -> 0 | I35: =0 -> 0 | J35: =1 -> 1 | K35: =Supuestos!$H$4*Cinematica!E5 -> 0 | L35: =SUMPRODUCT(B35:J35,Reacciones!$B$6:$J$6)-K35 -> 6.505213e-19
A36: BC ΣFx | B36: =0 -> 0 | C36: =0 -> 0 | D36: =-1 -> -1 | E36: =0 -> 0 | F36: =1 -> 1 | G36: =0 -> 0 | H36: =0 -> 0 | I36: =0 -> 0 | J36: =0 -> 0 | K36: =Supuestos!$F$5*Cinematica!AV5 -> 0.00066752072 | L36: =SUMPRODUCT(B36:J36,Reacciones!$B$6:$J$6)-K36 -> 0
A37: BC ΣFy | B37: =0 -> 0 | C37: =0 -> 0 | D37: =0 -> 0 | E37: =-1 -> -1 | F37: =0 -> 0 | G37: =1 -> 1 | H37: =0 -> 0 | I37: =0 -> 0 | J37: =0 -> 0 | K37: =Supuestos!$F$5*Cinematica!AW5+Supuestos!$G$5 -> 0.040694313 | L37: =SUMPRODUCT(B37:J37,Reacciones!$B$6:$J$6)-K37 -> 0
A38: BC ΣM_G | B38: =0 -> 0 | C38: =0 -> 0 | D38: =-Cinematica!AU5 -> -0.046248202 | E38: =Cinematica!AT5 -> 0.019002731 | F38: =-(Cinematica!O5-Cinematica!AU5) -> -0.046248202 | G38: =Cinematica!N5-Cinematica!AT5 -> 0.019002731 | H38: =0 -> 0 | I38: =0 -> 0 | J38: =0 -> 0 | K38: =Supuestos!$H$5*Cinematica!AB5 -> 6.7843277e-06 | L38: =SUMPRODUCT(B38:J38,Reacciones!$B$6:$J$6)-K38 -> 4.294457e-19
A39: CDP ΣFx | B39: =0 -> 0 | C39: =0 -> 0 | D39: =0 -> 0 | E39: =0 -> 0 | F39: =-1 -> -1 | G39: =0 -> 0 | H39: =1 -> 1 | I39: =0 -> 0 | J39: =0 -> 0 | K39: =Supuestos!$F$6*Cinematica!AZ5 -> -0.00015460998 | L39: =SUMPRODUCT(B39:J39,Reacciones!$B$6:$J$6)-K39 -> 5.9631119e-19
A40: CDP ΣFy | B40: =0 -> 0 | C40: =0 -> 0 | D40: =0 -> 0 | E40: =0 -> 0 | F40: =0 -> 0 | G40: =-1 -> -1 | H40: =0 -> 0 | I40: =1 -> 1 | J40: =0 -> 0 | K40: =Supuestos!$F$6*Cinematica!BA5+Supuestos!$G$6 -> 0.1117612 | L40: =SUMPRODUCT(B40:J40,Reacciones!$B$6:$J$6)-K40 -> 0
A41: CDP ΣM_G | B41: =0 -> 0 | C41: =0 -> 0 | D41: =0 -> 0 | E41: =0 -> 0 | F41: =Cinematica!Q5-Cinematica!AY5 -> 0.053308425 | G41: =-(Cinematica!P5-Cinematica!AX5) -> 0.10893599 | H41: =Cinematica!AY5 -> -0.009353589 | I41: =-Cinematica!AX5 -> -0.019114099 | J41: =0 -> 0 | K41: =Supuestos!$H$6*Cinematica!AC5 -> 9.5155035e-05 | L41: =SUMPRODUCT(B41:J41,Reacciones!$B$6:$J$6)-K41 -> -4.0657581e-19
A42: Soluciones (se muestran en hoja Reacciones)
A45: ="Posición 4 t="&TEXT(Cinematica!A6,"0.000")&" s θ_AB="&TEXT(Cinematica!B6,"0.0")&"°" -> Posición 4 t=1.766 s θ_AB=-246.9°
A46: Ecuación | B46: Ax | C46: Ay | D46: Bx | E46: By | F46: Cx | G46: Cy | H46: Dx | I46: Dy | J46: M_A | K46: RHS | L46: Residual
A47: AB ΣFx | B47: =1 -> 1 | C47: =0 -> 0 | D47: =1 -> 1 | E47: =0 -> 0 | F47: =0 -> 0 | G47: =0 -> 0 | H47: =0 -> 0 | I47: =0 -> 0 | J47: =0 -> 0 | K47: =Supuestos!$F$4*Cinematica!AR6 -> 0.00020300113 | L47: =SUMPRODUCT(B47:J47,Reacciones!$B$7:$J$7)-K47 -> 3.5236571e-19
...

Sheet Reacciones
A1: REACCIONES Y TORQUE DEL SERVO (sin masa de tornillos)
A3: t (s) | B3: Ax | C3: Ay | D3: Bx | E3: By | F3: Cx | G3: Cy | H3: Dx | I3: Dy | J3: M_A | K3: R_A | L3: R_B | M3: R_C | N3: R_D | O3: res_max
A4: =Cinematica!A3 -> 0.9 | B4: =INDEX(MMULT(MINVERSE('Sistema Reacciones'!$B$5:$J$13),'Sistema Reacciones'!$K$5:$K$13),1,1) -> 0.00059321897 | C4: =INDEX(MMULT(MINVERSE('Sistema Reacciones'!$B$5:$J$13),'Sistema Reacciones'!$K$5:$K$13),2,1) -> 0.04875746 | D4: =INDEX(MMULT(MINVERSE('Sistema Reacciones'!$B$5:$J$13),'Sistema Reacciones'!$K$5:$K$13),3,1) -> -0.00016782926 | E4: =INDEX(MMULT(MINVERSE('Sistema Reacciones'!$B$5:$J$13),'Sistema Reacciones'!$K$5:$K$13),4,1) -> -0.020652047 | F4: =INDEX(MMULT(MINVERSE('Sistema Reacciones'!$B$5:$J$13),'Sistema Reacciones'!$K$5:$K$13),5,1) -> 0.00052342221 | G4: =INDEX(MMULT(MINVERSE('Sistema Reacciones'!$B$5:$J$13),'Sistema Reacciones'!$K$5:$K$13),6,1) -> 0.022089001 | H4: =INDEX(MMULT(MINVERSE('Sistema Reacciones'!$B$5:$J$13),'Sistema Reacciones'!$K$5:$K$13),7,1) -> 0.00046308131 | I4: =INDEX(MMULT(MINVERSE('Sistema Reacciones'!$B$5:$J$13),'Sistema Reacciones'!$K$5:$K$13),8,1) -> 0.13267085 | J4: =INDEX(MMULT(MINVERSE('Sistema Reacciones'!$B$5:$J$13),'Sistema Reacciones'!$K$5:$K$13),9,1) -> -0.0014157841 | K4: =SQRT(B4^2+C4^2) -> 0.048761069 | L4: =SQRT(D4^2+E4^2) -> 0.020652729 | M4: =SQRT(F4^2+G4^2) -> 0.022095202 | N4: =SQRT(H4^2+I4^2) -> 0.13267166 | O4: =MAX(ABS('Sistema Reacciones'!L5),ABS('Sistema Reacciones'!L6),ABS('Sistema Reacciones'!L7),ABS('Sistema Reacciones'!L8),ABS('Sistema Reacciones'!L9),ABS('Sistema Reacciones'!L10),ABS('Sistema Reacciones'!L11),ABS('Sistema Reacciones'!L12),ABS('Sistema Reacciones'!L13)) -> 1.1926224e-18
A5: =Cinematica!A4 -> 1.266 | B5: =INDEX(MMULT(MINVERSE('Sistema Reacciones'!$B$19:$J$27),'Sistema Reacciones'!$K$19:$K$27),1,1) -> 0.00010333469 | C5: =INDEX(MMULT(MINVERSE('Sistema Reacciones'!$B$19:$J$27),'Sistema Reacciones'!$K$19:$K$27),2,1) -> 0.046436468 | D5: =INDEX(MMULT(MINVERSE('Sistema Reacciones'!$B$19:$J$27),'Sistema Reacciones'!$K$19:$K$27),3,1) -> 0.00041186826 | E5: =INDEX(MMULT(MINVERSE('Sistema Reacciones'!$B$19:$J$27),'Sistema Reacciones'!$K$19:$K$27),4,1) -> -0.018673403 | F5: =INDEX(MMULT(MINVERSE('Sistema Reacciones'!$B$19:$J$27),'Sistema Reacciones'!$K$19:$K$27),5,1) -> 0.0015842441 | G5: =INDEX(MMULT(MINVERSE('Sistema Reacciones'!$B$19:$J$27),'Sistema Reacciones'!$K$19:$K$27),6,1) -> 0.023081549 | H5: =INDEX(MMULT(MINVERSE('Sistema Reacciones'!$B$19:$J$27),'Sistema Reacciones'!$K$19:$K$27),7,1) -> 0.0011307572 | I5: =INDEX(MMULT(MINVERSE('Sistema Reacciones'!$B$19:$J$27),'Sistema Reacciones'!$K$19:$K$27),8,1) -> 0.13419974 | J5: =INDEX(MMULT(MINVERSE('Sistema Reacciones'!$B$19:$J$27),'Sistema Reacciones'!$K$19:$K$27),9,1) -> -0.0016200752 | K5: =SQRT(B5^2+C5^2) -> 0.046436583 | L5: =SQRT(D5^2+E5^2) -> 0.018677944 | M5: =SQRT(F5^2+G5^2) -> 0.023135854 | N5: =SQRT(H5^2+I5^2) -> 0.13420451 | O5: =MAX(ABS('Sistema Reacciones'!L19),ABS('Sistema Reacciones'!L20),ABS('Sistema Reacciones'!L21),ABS('Sistema Reacciones'!L22),ABS('Sistema Reacciones'!L23),ABS('Sistema Reacciones'!L24),ABS('Sistema Reacciones'!L25),ABS('Sistema Reacciones'!L26),ABS('Sistema Reacciones'!L27)) -> 2.7647155e-18
A6: =Cinematica!A5 -> 1.633 | B6: =INDEX(MMULT(MINVERSE('Sistema Reacciones'!$B$33:$J$41),'Sistema Reacciones'!$K$33:$K$41),1,1) -> -0.00072733479 | C6: =INDEX(MMULT(MINVERSE('Sistema Reacciones'!$B$33:$J$41),'Sistema Reacciones'!$K$33:$K$41),2,1) -> 0.044157842 | D6: =INDEX(MMULT(MINVERSE('Sistema Reacciones'!$B$33:$J$41),'Sistema Reacciones'!$K$33:$K$41),3,1) -> 0.0010815298 | E6: =INDEX(MMULT(MINVERSE('Sistema Reacciones'!$B$33:$J$41),'Sistema Reacciones'!$K$33:$K$41),4,1) -> -0.016724162 | F6: =INDEX(MMULT(MINVERSE('Sistema Reacciones'!$B$33:$J$41),'Sistema Reacciones'!$K$33:$K$41),5,1) -> 0.0017490505 | G6: =INDEX(MMULT(MINVERSE('Sistema Reacciones'!$B$33:$J$41),'Sistema Reacciones'!$K$33:$K$41),6,1) -> 0.023970151 | H6: =INDEX(MMULT(MINVERSE('Sistema Reacciones'!$B$33:$J$41),'Sistema Reacciones'!$K$33:$K$41),7,1) -> 0.0015944405 | I6: =INDEX(MMULT(MINVERSE('Sistema Reacciones'!$B$33:$J$41),'Sistema Reacciones'!$K$33:$K$41),8,1) -> 0.13573135 | J6: =INDEX(MMULT(MINVERSE('Sistema Reacciones'!$B$33:$J$41),'Sistema Reacciones'!$K$33:$K$41),9,1) -> -0.0010089499 | K6: =SQRT(B6^2+C6^2) -> 0.044163832 | L6: =SQRT(D6^2+E6^2) -> 0.016759096 | M6: =SQRT(F6^2+G6^2) -> 0.024033878 | N6: =SQRT(H6^2+I6^2) -> 0.13574072 | O6: =MAX(ABS('Sistema Reacciones'!L33),ABS('Sistema Reacciones'!L34),ABS('Sistema Reacciones'!L35),ABS('Sistema Reacciones'!L36),ABS('Sistema Reacciones'!L37),ABS('Sistema Reacciones'!L38),ABS('Sistema Reacciones'!L39),ABS('Sistema Reacciones'!L40),ABS('Sistema Reacciones'!L41)) -> 6.505213e-19
A7: =Cinematica!A6 -> 1.766 | B7: =INDEX(MMULT(MINVERSE('Sistema Reacciones'!$B$47:$J$55),'Sistema Reacciones'!$K$47:$K$55),1,1) -> -0.0012510708 | C7: =INDEX(MMULT(MINVERSE('Sistema Reacciones'!$B$47:$J$55),'Sistema Reacciones'!$K$47:$K$55),2,1) -> 0.042570374 | D7: =INDEX(MMULT(MINVERSE('Sistema Reacciones'!$B$47:$J$55),'Sistema Reacciones'!$K$47:$K$55),3,1) -> 0.0014540719 | E7: =INDEX(MMULT(MINVERSE('Sistema Reacciones'!$B$47:$J$55),'Sistema Reacciones'!$K$47:$K$55),4,1) -> -0.015235444 | F7: =INDEX(MMULT(MINVERSE('Sistema Reacciones'!$B$47:$J$55),'Sistema Reacciones'!$K$47:$K$55),5,1) -> 0.0015217317 | G7: =INDEX(MMULT(MINVERSE('Sistema Reacciones'!$B$47:$J$55),'Sistema Reacciones'!$K$47:$K$55),6,1) -> 0.025097377 | H7: =INDEX(MMULT(MINVERSE('Sistema Reacciones'!$B$47:$J$55),'Sistema Reacciones'!$K$47:$K$55),7,1) -> 0.0017905315 | I7: =INDEX(MMULT(MINVERSE('Sistema Reacciones'!$B$47:$J$55),'Sistema Reacciones'!$K$47:$K$55),8,1) -> 0.13710074 | J7: =INDEX(MMULT(MINVERSE('Sistema Reacciones'!$B$47:$J$55),'Sistema Reacciones'!$K$47:$K$55),9,1) -> -0.00050477799 | K7: =SQRT(B7^2+C7^2) -> 0.042588754 | L7: =SQRT(D7^2+E7^2) -> 0.015304675 | M7: =SQRT(F7^2+G7^2) -> 0.025143468 | N7: =SQRT(H7^2+I7^2) -> 0.13711243 | O7: =MAX(ABS('Sistema Reacciones'!L47),ABS('Sistema Reacciones'!L48),ABS('Sistema Reacciones'!L49),ABS('Sistema Reacciones'!L50),ABS('Sistema Reacciones'!L51),ABS('Sistema Reacciones'!L52),ABS('Sistema Reacciones'!L53),ABS('Sistema Reacciones'!L54),ABS('Sistema Reacciones'!L55)) -> 6.7762636e-19
A8: =Cinematica!A7 -> 1.899 | B8: =INDEX(MMULT(MINVERSE('Sistema Reacciones'!$B$61:$J$69),'Sistema Reacciones'!$K$61:$K$69),1,1) -> -0.0015547094 | C8: =INDEX(MMULT(MINVERSE('Sistema Reacciones'!$B$61:$J$69),'Sistema Reacciones'!$K$61:$K$69),2,1) -> 0.039453602 | D8: =INDEX(MMULT(MINVERSE('Sistema Reacciones'!$B$61:$J$69),'Sistema Reacciones'!$K$61:$K$69),3,1) -> 0.0015510972 | E8: =INDEX(MMULT(MINVERSE('Sistema Reacciones'!$B$61:$J$69),'Sistema Reacciones'!$K$61:$K$69),4,1) -> -0.012160145 | F8: =INDEX(MMULT(MINVERSE('Sistema Reacciones'!$B$61:$J$69),'Sistema Reacciones'!$K$61:$K$69),5,1) -> 0.00076382762 | G8: =INDEX(MMULT(MINVERSE('Sistema Reacciones'!$B$61:$J$69),'Sistema Reacciones'!$K$61:$K$69),6,1) -> 0.027814199 | H8: =INDEX(MMULT(MINVERSE('Sistema Reacciones'!$B$61:$J$69),'Sistema Reacciones'!$K$61:$K$69),7,1) -> 0.0016511767 | I8: =INDEX(MMULT(MINVERSE('Sistema Reacciones'!$B$61:$J$69),'Sistema Reacciones'!$K$61:$K$69),8,1) -> 0.1401538 | J8: =INDEX(MMULT(MINVERSE('Sistema Reacciones'!$B$61:$J$69),'Sistema Reacciones'!$K$61:$K$69),9,1) -> 8.66515e-05 | K8: =SQRT(B8^2+C8^2) -> 0.039484223 | L8: =SQRT(D8^2+E8^2) -> 0.012258672 | M8: =SQRT(F8^2+G8^2) -> 0.027824685 | N8: =SQRT(H8^2+I8^2) -> 0.14016353 | O8: =MAX(ABS('Sistema Reacciones'!L61),ABS('Sistema Reacciones'!L62),ABS('Sistema Reacciones'!L63),ABS('Sistema Reacciones'!L64),ABS('Sistema Reacciones'!L65),ABS('Sistema Reacciones'!L66),ABS('Sistema Reacciones'!L67),ABS('Sistema Reacciones'!L68),ABS('Sistema Reacciones'!L69)) -> 1.6805134e-18
A9: =Cinematica!A8 -> 2.099 | B9: =INDEX(MMULT(MINVERSE('Sistema Reacciones'!$B$75:$J$83),'Sistema Reacciones'!$K$75:$K$83),1,1) -> 0.0019004555 | C9: =INDEX(MMULT(MINVERSE('Sistema Reacciones'!$B$75:$J$83),'Sistema Reacciones'!$K$75:$K$83),2,1) -> 0.04009934 | D9: =INDEX(MMULT(MINVERSE('Sistema Reacciones'!$B$75:$J$83),'Sistema Reacciones'!$K$75:$K$83),3,1) -> -0.0022751529 | E9: =INDEX(MMULT(MINVERSE('Sistema Reacciones'!$B$75:$J$83),'Sistema Reacciones'!$K$75:$K$83),4,1) -> -0.0126453 | F9: =INDEX(MMULT(MINVERSE('Sistema Reacciones'!$B$75:$J$83),'Sistema Reacciones'!$K$75:$K$83),5,1) -> -0.0026081246 | G9: =INDEX(MMULT(MINVERSE('Sistema Reacciones'!$B$75:$J$83),'Sistema Reacciones'!$K$75:$K$83),6,1) -> 0.027547491 | H9: =INDEX(MMULT(MINVERSE('Sistema Reacciones'!$B$75:$J$83),'Sistema Reacciones'!$K$75:$K$83),7,1) -> -0.0028681088 | I9: =INDEX(MMULT(MINVERSE('Sistema Reacciones'!$B$75:$J$83),'Sistema Reacciones'!$K$75:$K$83),8,1) -> 0.13991255 | J9: =INDEX(MMULT(MINVERSE('Sistema Reacciones'!$B$75:$J$83),'Sistema Reacciones'!$K$75:$K$83),9,1) -> 0.00088291509 | K9: =SQRT(B9^2+C9^2) -> 0.04014435 | L9: =SQRT(D9^2+E9^2) -> 0.012848344 | M9: =SQRT(F9^2+G9^2) -> 0.027670681 | N9: =SQRT(H9^2+I9^2) -> 0.13994194 | O9: =MAX(ABS('Sistema Reacciones'!L75),ABS('Sistema Reacciones'!L76),ABS('Sistema Reacciones'!L77),ABS('Sistema Reacciones'!L78),ABS('Sistema Reacciones'!L79),ABS('Sistema Reacciones'!L80),ABS('Sistema Reacciones'!L81),ABS('Sistema Reacciones'!L82),ABS('Sistema Reacciones'!L83)) -> 7.5894152e-19

Sheet Procedimiento
A1: PROCEDIMIENTO RESUMIDO
A3: 1. Descripción | B3: Mecanismo plano accionado por servo. A es el eje del servo; AB mueve BC; BC mueve la barra CDP que gira alrededor de D; P es el extremo final.
A4: 2. Supuesto de entrada | B4: La velocidad angular del servo se tomó constante: ω_AB = -2.701947 rad/s, por lo tanto α_AB = 0.
A5: 3. Posición de B | B5: x_B=AB*cos(θ_AB), y_B=AB*sin(θ_AB).
A6: 4. Posición de C | B6: Se encuentra por intersección de dos círculos, imponiendo BC=0.1 m y CD=0.1 m.
A7: 5. Movimiento de AB | B7: Rotación pura alrededor de A: v_B=ω_AB(-y_B,x_B), a_B=α_AB(-y_B,x_B)-ω_AB^2(x_B,y_B).
A8: 6. Movimiento de BC | B8: Movimiento plano general: v_C=v_B+ω_BC(-y_CB,x_CB); a_C=a_B+α_BC(-y_CB,x_CB)-ω_BC^2(x_CB,y_CB).
A9: 7. Movimiento de CDP | B9: Rotación pura alrededor de D: v_C=ω_CD(-y_CD,x_CD); a_C=α_CD(-y_CD,x_CD)-ω_CD^2(x_CD,y_CD).
A10: 8. Punto P | B10: r_P/D = -(DP/CD) r_C/D porque P está del lado opuesto a C respecto de D.
A11: 9. Centros de masa | B11: AB y BC son uniformes: G_AB a la mitad de AB y G_BC a la mitad de BC. Para CDP se usa CG=121.28 mm de Inventor, por eso r_G/D=-0.2128 r_C/D.
A12: 10. Dinámica | B12: Para cada barra se usa ΣFx=m a_Gx, ΣFy=m a_Gy y ΣM_G=I_G α. El peso entra en ΣFy, no en ΣM_G porque actúa en G.
A13: 11. Incógnitas | B13: Se resuelven Ax, Ay, Bx, By, Cx, Cy, Dx, Dy y M_A.
A14: 12. Verificación | B14: La auditoría confirma BC=0.100 m, CD=0.100 m y residuos de reacciones del orden de 10^-16 o menor.

Sheet Graficas
A1: T | B1: A | C1: B | D1: C | E1: D | F1: P | I1: t (s) | J1: Ax (N) | K1: Ay (N) | L1: Bx (N) | M1: By (N) | N1: Cx (N) | O1: Cy (N) | P1: Dx (N) | Q1: Dy (N) | R1: MA (N·m) | S1: Mag A | T1: Mag B | U1: Mag C | V1: Mag D
A2: 0.9 | B2: -145.3 | C2: -145.3 | D2: 93.8 | E2: 42.24 | F2: 27.77 | I2: 0.9 | J2: 0.000593 | K2: 0.048757 | L2: -0.000168 | M2: -0.020652 | N2: 0.000523 | O2: 0.022089 | P2: 0.000463 | Q2: 0.132671 | R2: -0.001416 | S2: =SQRT(J2^2 + K2^2) -> 0.048760606 | T2: =SQRT(L2^2 + M2^2) -> 0.020652683 | U2: =SQRT(N2^2 + O2^2) -> 0.022095191 | V2: =SQRT(P2^2 + Q2^2) -> 0.13267181
A3: 1.266 | B3: -185.3 | C3: -185.3 | D3: 93.6 | E3: 42.24 | F3: 19.59 | I3: 1.266 | J3: 0.000103 | K3: 0.046436 | L3: 0.000412 | M3: -0.018673 | N3: 0.001584 | O3: 0.023082 | P3: 0.001131 | Q3: 0.1342 | R3: -0.00162 | S3: =SQRT(J3^2 + K3^2) -> 0.046436114 | T3: =SQRT(L3^2 + M3^2) -> 0.018677545 | U3: =SQRT(N3^2 + O3^2) -> 0.023136287 | V3: =SQRT(P3^2 + Q3^2) -> 0.13420477
A4: 1.633 | B4: -226.8 | C4: -226.8 | D4: 88.32 | E4: 42.24 | F4: 9.92 | I4: 1.633 | J4: -0.000727 | K4: 0.044158 | L4: 0.001082 | M4: -0.016724 | N4: 0.001749 | O4: 0.02397 | P4: 0.001594 | Q4: 0.135731 | R4: -0.001009 | S4: =SQRT(J4^2 + K4^2) -> 0.044163984 | T4: =SQRT(L4^2 + M4^2) -> 0.016758965 | U4: =SQRT(N4^2 + O4^2) -> 0.024033724 | V4: =SQRT(P4^2 + Q4^2) -> 0.13574036
A5: 1.766 | B5: -246.9 | C5: -246.9 | D5: 85.58 | E5: 42.24 | F5: 6.15 | I5: 1.766 | J5: -0.001251 | K5: 0.04257 | L5: 0.001454 | M5: -0.015235 | N5: 0.001522 | O5: 0.025097 | P5: 0.001791 | Q5: 0.137101 | R5: -0.000505 | S5: =SQRT(J5^2 + K5^2) -> 0.042588378 | T5: =SQRT(L5^2 + M5^2) -> 0.015304226 | U5: =SQRT(N5^2 + O5^2) -> 0.025143108 | V5: =SQRT(P5^2 + Q5^2) -> 0.1371127
A6: 1.899 | B6: -270.4 | C6: -270.4 | D6: 83.66 | E6: 42.24 | F6: 3.69 | I6: 1.899 | J6: -0.001555 | K6: 0.039454 | L6: 0.001551 | M6: -0.01216 | N6: 0.000764 | O6: 0.027814 | P6: 0.001651 | Q6: 0.140154 | R6: 8.7e-05 | S6: =SQRT(J6^2 + K6^2) -> 0.039484632 | T6: =SQRT(L6^2 + M6^2) -> 0.012258515 | U6: =SQRT(N6^2 + O6^2) -> 0.027824491 | V6: =SQRT(P6^2 + Q6^2) -> 0.14016372
A7: 2.099 | B7: -316.4 | C7: -316.4 | D7: 88.29 | E7: 42.24 | F7: 9.88 | I7: 2.099 | J7: 0.0019 | K7: 0.040099 | L7: -0.002275 | M7: -0.012645 | N7: -0.002608 | O7: 0.027547 | P7: -0.002868 | Q7: 0.139913 | R7: 0.000883 | S7: =SQRT(J7^2 + K7^2) -> 0.040143988 | T7: =SQRT(L7^2 + M7^2) -> 0.012848021 | U7: =SQRT(N7^2 + O7^2) -> 0.02767018 | V7: =SQRT(P7^2 + Q7^2) -> 0.13994239
A10: t | B10: w_BC | C10: w_CD | D10: a ang_BC | E10: a ang_CD | F10: |vB| | G10: |aB| | H10: |vC| | I10: |aC| | J10: |vP| | K10: |aP|
A11: 0.9 | B11: -0.6294 | C11: -0.8979 | D11: 2.802 | E11: -2.6323 | F11: 0.1351 | G11: 0.365 | H11: 0.0898 | I11: 0.2753 | J11: 0.1033 | K11: 0.3166
A12: 1.266 | B12: -0.0039 | C12: -1.3496 | D12: 1.9531 | E12: -0.6953 | F12: 0.1351 | G12: 0.365 | H12: 0.135 | I12: 0.195 | J12: 0.1552 | K12: 0.2242
A13: 1.633 | B13: 0.4791 | C13: -1.2323 | D13: 1.9145 | E13: 1.6456 | F13: 0.1351 | G13: 0.365 | H13: 0.1232 | I13: 0.2239 | J13: 0.1417 | K13: 0.2575
A14: 1.766 | B14: 0.7607 | C14: -0.9217 | D14: 2.4882 | E14: 3.2305 | F14: 0.1351 | G14: 0.365 | H14: 0.0922 | I14: 0.334 | J14: 0.106 | K14: 0.3841
A15: 1.899 | B15: 1.2127 | C15: -0.242 | D15: 3.4595 | E15: 5.8441 | F15: 0.1351 | G15: 0.365 | H15: 0.0242 | I15: 0.5844 | J15: 0.0278 | K15: 0.6721
A16: 2.099 | B16: 1.7944 | C16: 1.737 | D16: -2.8313 | E16: 3.6961 | F16: 0.1351 | G16: 0.365 | H16: 0.1737 | I16: 0.4771 | J16: 0.1998 | K16: 0.5487
